Workbook

Sheet Summary
A1: Large-Scale Validation — MDLAES vs. Standard AES vs. [5] Abikoye et al. (2019)
A3: Table 10 — Plaintext Sensitivity, N = 1,000 random (PT, K) pairs, random plaintext bit-flip
A4: Metric | B4: Std AES (paper) | C4: Std AES (this run) | D4: [5] Abikoye (paper) | E4: [5] Abikoye (this run) | F4: MDLAES (paper) | G4: MDLAES (this run)
A5: Mean AE (%) | B5: 50.14 | C5: =AVERAGE(Table10!E2:E1001)*100 -> 49.955469 | D5: 49.96 | E5: =AVERAGE(Table10!F2:F1001)*100 -> 50.074219 | F5: 50.06 | G5: =AVERAGE(Table10!G2:G1001)*100 -> 50.157031
A6: Std Deviation (pp) | B6: 4.35 | C6: =_xlfn.STDEV.P(Table10!E2:E1001)*100 -> 4.6039263 | D6: 4.36 | E6: =_xlfn.STDEV.P(Table10!F2:F1001)*100 -> 4.4451666 | F6: 4.37 | G6: =_xlfn.STDEV.P(Table10!G2:G1001)*100 -> 4.4795406
A7: SAC compliance (AE≥50%) | B7: 54.1% | C7: =COUNTIF(Table10!E2:E1001,">=0.5")/1000 -> 0.519 | D7: 51.6% | E7: =COUNTIF(Table10!F2:F1001,">=0.5")/1000 -> 0.535 | F7: 52.5% | G7: =COUNTIF(Table10!G2:G1001,">=0.5")/1000 -> 0.539
A10: Table 11 — Key Sensitivity, N = 1,000 random keys, fixed PT = 'I Love Unilorin!', random key bit-flip
A11: Metric | B11: Std AES (paper) | C11: Std AES (this run) | D11: [5] Abikoye (paper) | E11: [5] Abikoye (this run) | F11: MDLAES (paper) | G11: MDLAES (this run)
A12: Mean AE (%) | B12: 49.84 | C12: =AVERAGE(Table11!D2:D1001)*100 -> 50.140625 | D12: 50.01 | E12: =AVERAGE(Table11!E2:E1001)*100 -> 49.85 | F12: 49.84 | G12: =AVERAGE(Table11!F2:F1001)*100 -> 49.821875
A13: Std Deviation (pp) | B13: 4.47 | C13: =_xlfn.STDEV.P(Table11!D2:D1001)*100 -> 4.4922622 | D13: 4.47 | E13: =_xlfn.STDEV.P(Table11!E2:E1001)*100 -> 4.4463446 | F13: 4.39 | G13: =_xlfn.STDEV.P(Table11!F2:F1001)*100 -> 4.5617251
A14: SAC compliance (AE≥50%) | B14: 53.2% | C14: =COUNTIF(Table11!D2:D1001,">=0.5")/1000 -> 0.532 | D14: 53.3% | E14: =COUNTIF(Table11!E2:E1001,">=0.5")/1000 -> 0.522 | F14: 51.2% | G14: =COUNTIF(Table11!F2:F1001,">=0.5")/1000 -> 0.516
A17: Table 12 — K² Invertibility, N = 10,000 uniformly random 16-byte keys
A18: Metric | B18: Paper | C18: Run percentages
A19: Invertible K² (count) | B19: 9958 | C19: =COUNTIF(Table12!C2:C10001,TRUE()) -> 9971
A20: Invertible K² (rate) | B20: 99.58% | C20: =COUNTIF(Table12!C2:C10001,TRUE())/10000 -> 0.9971
A21: Singular K² (count) | B21: 42 | C21: =COUNTIF(Table12!C2:C10001,FALSE()) -> 29
A24: Table 13 — Ciphertext Entropy & Bit Balance, N = 1,000 random (PT, K) pairs
A25: Metric | B25: Paper: Mean | C25: Run Mean | D25: Paper: SD | E25: Run SD | F25: Paper Min | G25: Run Min | H25: Paper:Max | I25: Run Max
A26: Shannon entropy (bits/byte) | B26: 3.9425 | C26: =AVERAGE(Table13!E2:E1001) -> 3.9431226 | D26: 0.084 | E26: =_xlfn.STDEV.P(Table13!E2:E1001) -> 0.083939153 | F26: 3.5 | G26: =MIN(Table13!E2:E1001) -> 3.375 | H26: 4 | I26: =MAX(Table13!E2:E1001) -> 4
A27: Bit balance (% of 1-bits) | B27: 50.10% | C27: =AVERAGE(Table13!F2:F1001)/100 -> 0.49817188 | D27: 4.45 pp | E27: =_xlfn.STDEV.P(Table13!F2:F1001)/100 -> 0.044211602 | F27: 35.16% | G27: =MIN(Table13!F2:F1001)/100 -> 0.375 | H27: 64.06% | I27: =MAX(Table13!F2:F1001)/100 -> 0.6953125

Sheet Table10
A1: Trial | B1: Plaintext (hex) | C1: Key (hex) | D1: Bit position flipped | E1: AE Std AES | F1: AE [5] Abikoye | G1: AE MDLAES
A2: 1 | B2: 390C8C7D7247342CD8100F2F6F770D65 | C2: D670E58E0351D8AE8E4F6EAC342FC231 | D2: 91 | E2: 0.53125 | F2: 0.5 | G2: 0.546875
A3: 2 | B3: B08716EB3FC12896B962231774942877 | C3: 33C28EE8BA53BDB56B8824577D53ECC2 | D3: 69 | E3: 0.5390625 | F3: 0.4609375 | G3: 0.5234375
A4: 3 | B4: 70A61C7510A1CD89216CA16CFFCAEA49 | C4: 87477E86DBCCB97046FC2E18384E51D8 | D4: 16 | E4: 0.4453125 | F4: 0.5546875 | G4: 0.546875
A5: 4 | B5: C5C3EF80053A88AE3996DE50E801865B | C5: 3698654EBF5200A5FA0939B99D7A1D7B | D5: 20 | E5: 0.484375 | F5: 0.53125 | G5: 0.6171875
A6: 5 | B6: 2BF8234041F35487D86C669FCCBFE0E7 | C6: 3D7E7320AD0A757003241E752210A924 | D6: 60 | E6: 0.5078125 | F6: 0.515625 | G6: 0.59375
A7: 6 | B7: 8EF86D43F27CF2D0613031DCB5D8D2EF | C7: 1B321FCEAD377F6261E547D85D8EEC7F | D7: 19 | E7: 0.421875 | F7: 0.5078125 | G7: 0.46875
A8: 7 | B8: E23219072F7955D0F8F66DCD1E54C201 | C8: C787E892D8F94F61976F1D1FA01D19F4 | D8: 40 | E8: 0.484375 | F8: 0.484375 | G8: 0.578125
A9: 8 | B9: 1D295F232278CE3D7E1429D6A18568A0 | C9: 7A87CA4399EAA12504EA33256D8743B2 | D9: 17 | E9: 0.4453125 | F9: 0.515625 | G9: 0.4453125
A10: 9 | B10: 7DBD9150E09A04993544873B364F8B90 | C10: 6BAF6887FA801A2FD88D1601AA428652 | D10: 113 | E10: 0.4296875 | F10: 0.46875 | G10: 0.5234375
A11: 10 | B11: DA0439264C12BD4BDC41159DBA14B76B | C11: 7F34B5D04F79535AD30C5BAAD27F8851 | D11: 27 | E11: 0.46875 | F11: 0.5078125 | G11: 0.5078125
A12: 11 | B12: C313F07166EBB39C74720C62CCA88E23 | C12: 8EB3CCA90E3B855B871337DEB0A0DF3B | D12: 98 | E12: 0.5234375 | F12: 0.484375 | G12: 0.5390625
A13: 12 | B13: 618216DF0064BADC23A9A03F999ED1A7 | C13: CE974162D7C2599ACF009B926BDCA4EE | D13: 113 | E13: 0.5078125 | F13: 0.5234375 | G13: 0.4765625
... A1001: 1000 | B1001: D66A84582A52456870513EA00C07EC3E | C1001: 6C4603948B84B3D6E8F724BA8838EDC2 | D1001: 99 | E1001: 0.4921875 | F1001: 0.4921875 | G1001: 0.4765625

Sheet Table11
A1: Trial | B1: Key (hex) | C1: Bit position flipped | D1: AE Std AES | E1: AE [5] Abikoye | F1: AE MDLAES
A2: 1 | B2: 0397A1D5762B32CD9EBDE1CDFBE6CCBE | C2: 121 | D2: 0.5078125 | E2: 0.5078125 | F2: 0.4609375
A3: 2 | B3: DDC5CD80F6C917B44004AF47DF9FA8A4 | C3: 47 | D3: 0.4765625 | E3: 0.453125 | F3: 0.5
A4: 3 | B4: 24FBBA1F93FD44F949EFB8998D485502 | C4: 110 | D4: 0.421875 | E4: 0.4609375 | F4: 0.515625
A5: 4 | B5: 27B914D457EF76DD8D111FC2F5479CD4 | C5: 110 | D5: 0.4609375 | E5: 0.390625 | F5: 0.453125
A6: 5 | B6: 67137D532C837E1C632D617A7B0A2837 | C6: 28 | D6: 0.4765625 | E6: 0.46875 | F6: 0.4453125
A7: 6 | B7: 860ACDB580A5AFFFA3BE4494B64EC935 | C7: 87 | D7: 0.5546875 | E7: 0.453125 | F7: 0.4140625
A8: 7 | B8: 268D62D2EA81B1E86CA225E766E92D7B | C8: 84 | D8: 0.5 | E8: 0.46875 | F8: 0.5078125
A9: 8 | B9: B2CBD9DD7E68B5DF8022ED48A7C6173E | C9: 28 | D9: 0.4765625 | E9: 0.5390625 | F9: 0.5
A10: 9 | B10: DD4287D99CF0D75664C99146DCB93BF8 | C10: 117 | D10: 0.5703125 | E10: 0.5078125 | F10: 0.484375
A11: 10 | B11: 61DEF6182E0243FD271DA0410460E851 | C11: 25 | D11: 0.46875 | E11: 0.515625 | F11: 0.453125
A12: 11 | B12: 413FBB26158CB4C3579C8AD55D4D1230 | C12: 100 | D12: 0.5078125 | E12: 0.484375 | F12: 0.53125
A13: 12 | B13: ACD9D06F786CB4124F936043C441A57B | C13: 23 | D13: 0.5078125 | E13: 0.4765625 | F13: 0.4609375
... A1001: 1000 | B1001: 495DFB6AA7372CEFF6C97B84228C91F4 | C1001: 124 | D1001: 0.53125 | E1001: 0.53125 | F1001: 0.5

Sheet Table12
A1: Trial | B1: Key (hex) | C1: K² Invertible
A2: 1 | B2: E199E3D064E427096222E05BFEF9D61C | C2: =TRUE() -> TRUE
A3: 2 | B3: D1C3E0905904A90FA6F097CE594923CF | C3: =TRUE() -> TRUE
A4: 3 | B4: 6B86D0A92FCFA23AB1772B4320962477 | C4: =TRUE() -> TRUE
A5: 4 | B5: 40F718DCDAA13781DFD11B34FD07B379 | C5: =TRUE() -> TRUE
A6: 5 | B6: D4ED1236ABBD545EC69D274486C5BFAB | C6: =TRUE() -> TRUE
A7: 6 | B7: 4EB8F8E764A23AC27A47025C51ED3F2A | C7: =TRUE() -> TRUE
A8: 7 | B8: 6D29191E492A8E1A1082E2A1AAB8E4F8 | C8: =TRUE() -> TRUE
A9: 8 | B9: 7E946E4C5C75226041217BD4C7867FB7 | C9: =TRUE() -> TRUE
A10: 9 | B10: 058BC7FE6946E8A18BABDA48F23661EE | C10: =TRUE() -> TRUE
A11: 10 | B11: 1B498499C88DB20E1FC2CC0E98EF651B | C11: =TRUE() -> TRUE
A12: 11 | B12: D54BD994CFA9FF5A898999C77C2A488F | C12: =TRUE() -> TRUE
A13: 12 | B13: 471558EA9C7D162F284946135D25AE31 | C13: =TRUE() -> TRUE
... A956: 955 | B956: 448268951D668248C550D1719D82996B | C956: =TRUE() -> TRUE
A957: 956 | B957: 03803909BD9DACC7052373E8FB56C7FF | C957: =FALSE() -> FALSE
A958: 957 | B958: A2DECE0CFB639EADEB3F0BED35EA0BD1 | C958: =TRUE() -> TRUE
A959: 958 | B959: B4A51358DA9BF34444672785D3964E17 | C959: =TRUE() -> TRUE
A960: 959 | B960: 4D06E4CAB7F9DCCAE9B229699974978A | C960: =TRUE() -> TRUE
A961: 960 | B961: EDE2C25676CBC5D07EE4DA3D5D0285B4 | C961: =TRUE() -> TRUE
A962: 961 | B962: FCFED1F6811D81B20FCA55B22B3F2CB1 | C962: =TRUE() -> TRUE
A963: 962 | B963: BFDBAF5A48E93F61CF49840588DDF6F0 | C963: =TRUE() -> TRUE
A964: 963 | B964: 706579AD1B4DEDC550C56737872D74A2 | C964: =TRUE() -> TRUE
A965: 964 | B965: 1162E6A02999245A0822250CC5FCF975 | C965: =TRUE() -> TRUE
A966: 965 | B966: D5A35978E89EEDD43E3BABAF90F4619B | C966: =TRUE() -> TRUE
A967: 966 | B967: 040138261FB6482E55870AF5D8D3F6C1 | C967: =TRUE() -> TRUE
A968: 967 | B968: 33C7C394B4677C66E974683E17E09AE0 | C968: =TRUE() -> TRUE
A969: 968 | B969: CC0C622C14F0E3EA61BC7E78D187288A | C969: =TRUE() -> TRUE
... A991: 990 | B991: F147D3F85C6C9B13DEE1FE4CF6AD65D5 | C991: =TRUE() -> TRUE
A992: 991 | B992: C7F81CE36A994034086837CB4566FFBE | C992: =FALSE() -> FALSE
A993: 992 | B993: 7D9A440EA8D2CF0BE972B757CAE6A2C6 | C993: =TRUE() -> TRUE
A994: 993 | B994: B45A03BF7C1363CB3C040889DE0AAA37 | C994: =TRUE() -> TRUE
A995: 994 | B995: 010B31AE0117F056CA8AD649E634D5E9 | C995: =TRUE() -> TRUE
A996: 995 | B996: B34204B87DAA8628BDFE5078FD855E80 | C996: =TRUE() -> TRUE
A997: 996 | B997: ED904CA631A1FB9EDBA62D97D8BFC16C | C997: =TRUE() -> TRUE
A998: 997 | B998: 38CA0F685E84F79B35FC40DC73B64446 | C998: =TRUE() -> TRUE
A999: 998 | B999: 05526D319F62134DB24C1405400F9452 | C999: =TRUE() -> TRUE
A1000: 999 | B1000: D417F458A17985C1FD00E3A812DE24C4 | C1000: =TRUE() -> TRUE
A1001: 1000 | B1001: 227F3C4D3EEB2CDE5EC8D8CEF3894752 | C1001: =TRUE() -> TRUE
A1002: 1001 | B1002: 7974939B9FCC232EEBA29ABCEA222AE1 | C1002: =TRUE() -> TRUE
A1003: 1002 | B1003: 0596839E24BA62C53E83AB246F25754D | C1003: =TRUE() -> TRUE
...

Sheet Table13
A1: Trial | B1: Plaintext (hex) | C1: Key (hex) | D1: Ciphertext (hex) | E1: Shannon entropy (bits/byte) | F1: Bit balance (%)
A2: 1 | B2: 1FC5362F0E2A22A74D323B2574F11EAD | C2: 1BA38584A809AD1613B2525A2348E002 | D2: 064B7F19E22E591C38736EE862ECB0E7 | E2: 4 | F2: 50.78125
A3: 2 | B3: 7983D0E830B893EF2E2B68A392B7B23C | C3: B8347929179781AC861790C0F0E293E4 | D3: A574C825439360BCB11D77CB11A02A66 | E3: 4 | F3: 45.3125
A4: 3 | B4: A227A2382E4F6F96D7BD9790D2372998 | C4: 106B2036EB0A98F61D6D0BF731EAE36C | D4: C937304176E53B1039A3DC4A03AD27C7 | E4: 4 | F4: 47.65625
A5: 4 | B5: 1EB8292873999728A181D499FE0EC57A | C5: 7940BD8298D6917D1F99135CB96231BE | D5: E572C73CCC1106FA96711ACBA0BEF05D | E5: 4 | F5: 50.78125
A6: 5 | B6: 7F04F0D8E1470A039E2DD84F6E036722 | C6: FDD16500535E5DDFE1B5ED483E5E1106 | D6: 161A401CCD20075399AABBD1B7AD9116 | E6: 3.875 | F6: 45.3125
A7: 6 | B7: 62ED8E945968651921B6EC6C16E11EA4 | C7: 9DE2A2D6898CEDD29162C8F1E7BE2B9B | D7: 69CEE69E6D29B7DA678DA2458B7356EB | E7: 4 | F7: 56.25
A8: 7 | B8: 093DA4AC5714A5CE69C929856FEE7DC0 | C8: 9E500B3CF6E975FD99C3558F3EEBC5E3 | D8: 81839AD6A46BD0A7687E13D2B76B959F | E8: 3.875 | F8: 52.34375
A9: 8 | B9: 536C5160365D8FACDE4FECE1667B4141 | C9: C099F5FAD8FEA1F14033E970678C79EA | D9: 3C27F131DC519D69672C41771681E2A9 | E9: 4 | F9: 48.4375
A10: 9 | B10: 0A2CC23D47506CC87CF08742C7FB9422 | C10: 4A853C02E6C9C62FF850FB0C536DE923 | D10: A8F90ADE93F6A0FC1238DEFF70D00AFE | E10: 3.75 | F10: 53.90625
A11: 10 | B11: 9A953769C25FEAF5328BD006DED48E45 | C11: A6F041D6A78EB4E61F0251853EA883ED | D11: 948F284E7B1A2D8B1C3C4781EA02013F | E11: 4 | F11: 44.53125
A12: 11 | B12: 5014774B6BA2EA81BB9B084D4097BD08 | C12: 4B41C191F7E62C1910FDA09128A9CA76 | D12: 653442AFBA7F021E3FF617699EED159A | E12: 4 | F12: 54.6875
A13: 12 | B13: 2F4B5B9D035344E0D2C803BDDC6EB3B6 | C13: AEDBE8E6692C97BABB580936D9BD4AC3 | D13: 44ACD4E52B0E2FE8403B0BCF55ED3977 | E13: 4 | F13: 51.5625
... A1001: 1000 | B1001: FFD8195C28FF14A2A46FD1161C010EF3 | C1001: BB5F1C50702A289AD97FA4F9690EF85A | D1001: 27A665A0575AD070C520EC426280770C | E1001: 4 | F1001: 41.40625
